<mujoco model="bpd_bai_1">
  <compiler angle="radian"/>

  <asset>
    <!-- Visual meshes -->
    <mesh name="base_link" file="base_link.stl" scale="0.001 0.001 0.001"/>
    <mesh name="hip2hip_l" file="hip2hip_l.stl" scale="0.001 0.001 0.001"/>
    <mesh name="hip2hip_r" file="hip2hip_r.stl" scale="0.001 0.001 0.001"/>
    <mesh name="leg_u_l" file="leg_u_l.stl" scale="0.001 0.001 0.001"/>
    <mesh name="leg_u_r" file="leg_u_r.stl" scale="0.001 0.001 0.001"/>
    <mesh name="leg_l_l" file="leg_l_l.stl" scale="0.001 0.001 0.001"/>
    <mesh name="leg_l_r" file="leg_l_r.stl" scale="0.001 0.001 0.001"/>

    <!-- Collision meshes -->
    <mesh name="base_link_c" file="base_link_c.stl" scale="0.001 0.001 0.001"/>
    <mesh name="hip2hip_l_c" file="hip2hip_l_c.stl" scale="0.001 0.001 0.001"/>
    <mesh name="hip2hip_r_c" file="hip2hip_r_c.stl" scale="0.001 0.001 0.001"/>
    <mesh name="leg_u_l_c" file="leg_u_l_c.stl" scale="0.001 0.001 0.001"/>
    <mesh name="leg_u_r_c" file="leg_u_r_c.stl" scale="0.001 0.001 0.001"/>
    <mesh name="leg_l_l_c" file="leg_l_l_c.stl" scale="0.001 0.001 0.001"/>
    <mesh name="leg_l_r_c" file="leg_l_r_c.stl" scale="0.001 0.001 0.001"/>
  </asset>

  <worldbody>
    <light name="spotlight" mode="targetbodycom" target="base_link" pos="3 0 4"/>
    <!-- Define the floating base as a body with a free joint -->
    <body name="base_link" pos="0 0.0 0.32">
      <camera name="track" pos="0.846 -1.3 0.316" xyaxes="0.866 0.500 0.000 -0.171 0.296 0.940" mode="trackcom"/>
      <camera name="top" pos="-1 0 1" xyaxes="0 -1 0 0.7 0 0.7" mode="trackcom"/>
      <camera name="side" pos="0 -1 .3" xyaxes="1 0 0 0 1 2" mode="trackcom"/>
      <camera name="back" pos="-1 0 .3" xyaxes="0 -1 0 1 0 2" mode="trackcom"/>

      <inertial pos="-0.02 0.05 0.13"
                quat="0.999  -0.00012  0.00007  0.00054"
                mass="3.6762535"
                diaginertia="0.01195 0.01617 0.01837" />
                
      <joint name="base_free" type="free"/>

      <!-- IMU site -->
      <site name="imu_torso" pos="0 0.0 0.0" size="0.01"/>

      <!-- Base geoms -->
      <geom name="base_link_visual" type="mesh"
            mesh="base_link"
            rgba="0.8 0.8 0.8 1"
            contype="0" conaffinity="0"/>

      <!-- Left side -->
      <body name="hip2hip_l" pos="-0.020002 0.0862958 -0.026364" quat="0.887011 0.461749 0 0">
        <inertial pos="-0.023544 2.21095e-09 -0.0163088"
                  quat="0.653205 0.270783 0.270783 0.653205"
                  mass="0.0239012"
                  diaginertia="1.0071e-05 9.5693e-06 3.69117e-06"/>
        <joint name="J_HIP_L" pos="0 0 0"
               axis="0 -3.32035e-07 1"
               range="-0.95 2"
               actuatorfrcrange="-10 10"/>
        <geom name="hip2hip_l_visual" pos="-0.035 0.0135 -0.005"
              quat="0.5 0.5 0.5 -0.5"
              type="mesh"
              mesh="hip2hip_l"
              rgba="0.8 0.8 0.8 1"
              contype="0" conaffinity="0"/>

        <!-- Left upper leg -->
        <body name="leg_u_l" pos="-0.03 9.98141e-10 -0.041" quat="0.953717 0.300706 0 0">
          <inertial pos="0.024319 -0.0646496 0.00684158"
                    quat="0.687869 0.616325 -0.2401 0.298884"
                    mass="0.115327"
                    diaginertia="0.00029232 0.000291179 3.79894e-05"/>
          <joint name="J_AB_L" pos="0 0 0" axis="-1 0 0"
                 range="-1.75 0.5"
                 actuatorfrcrange="-10 10"/>
          <geom name="leg_u_l_visual" pos="0.0255 3.77476e-10 -1.57538e-09"
                quat="0.0308436 0.706434 -0.0308436 -0.706434"
                type="mesh"
                mesh="leg_u_l"
                rgba="0.8 0.8 0.8 1"
                contype="0" conaffinity="0"/>

          <!-- Left lower leg -->
          <body name="leg_l_l" pos="0.0255 -0.129549 0.0108322" quat="0.5 -0.5 -0.5 0.5">
            <inertial pos="-0.0765096 -0.0191126 -0.000454688"
                      quat="0.445202 0.547827 0.454391 0.543332"
                      mass="0.0520031"
                      diaginertia="0.000114788 0.000113123 9.32456e-06"/>
            <joint name="J_KNEE_L" pos="0 0 0"
                   axis="0.087156 -0.996195 0"
                   range="-2 0.9"
                   actuatorfrcrange="-10 10"/>
            <geom name="leg_l_l_visual" pos="-0.0870524 -0.0180516 -0.00136393"
                  quat="0 -0.0436194 0.999048 0"
                  type="mesh"
                  mesh="leg_l_l"
                  rgba="0.8 0.8 0.8 1"
                  contype="0" conaffinity="0"/>

            <!-- Example left foot geom or site (rename if needed) -->
            <!-- If this is your foot contact geom, just ensure it's named "left_foot" -->
            <geom name = "left_foot" pos="-0.15 -0.02 0" type="sphere" size="0.02" contype="1" conaffinity="1"/>
            <site name="left_foot" pos="-0.15 -0.02 0" size="0.01"/>

          </body>
        </body>
      </body>

      <!-- Right side -->
      <body name="hip2hip_r" pos="-0.020002 0.0141153 -0.026364" quat="0.887011 -0.461749 0 0">
        <inertial pos="-0.023544 -2.21095e-09 -0.0163088"
                  quat="0.653205 0.270783 0.270783 0.653205"
                  mass="0.0239012"
                  diaginertia="1.0071e-05 9.5693e-06 3.69117e-06"/>
        <joint name="J_HIP_R" pos="0 0 0"
               axis="0 3.32035e-07 1"
               range="-2 0.95"
               actuatorfrcrange="-10 10"/>
        <geom name="hip2hip_r_visual" pos="-0.035 0.0135 -0.005"
              quat="0.5 0.5 0.5 -0.5"
              type="mesh"
              mesh="hip2hip_r"
              rgba="0.8 0.8 0.8 1"
              contype="0" conaffinity="0"/>

        <!-- Right upper leg -->
        <body name="leg_u_r" pos="-0.03 -9.98141e-10 -0.041" quat="0.300706 0.953717 0 0">
          <inertial pos="0.024341 -0.0646517 -0.00681979"
                    quat="0.239917 0.299031 -0.687933 0.616253"
                    mass="0.115326"
                    diaginertia="0.000292419 0.000291104 3.79869e-05"/>
          <joint name="J_AB_R" pos="0 0 0" axis="-1 0 0"
                 range="-0.5 1.75"
                 actuatorfrcrange="-10 10"/>
          <geom name="leg_u_r_visual" pos="0.0255 3.77477e-10 1.57538e-09"
                quat="0.0308436 -0.706434 0.0308436 -0.706434"
                type="mesh"
                mesh="leg_u_r"
                rgba="0.8 0.8 0.8 1"
                contype="0" conaffinity="0"/>

          <!-- Right lower leg -->
          <body name="leg_l_r" pos="0.0255 -0.129549 -0.0108322" quat="0.5 -0.5 -0.5 0.5">
            <inertial pos="-0.0765097 0.0191126 -0.000454697"
                      quat="0.543331 0.454392 0.547826 0.445203"
                      mass="0.0520031"
                      diaginertia="0.000114788 0.000113123 9.32456e-06"/>
            <joint name="J_KNEE_R" pos="0 0 0"
                   axis="0.087156 0.996195 0"
                   range="-0.9 2"
                   actuatorfrcrange="-10 10"/>
            <geom name="leg_l_r_visual" pos="-0.0675048 0.0210103 -0.00136393"
                  quat="0.0436194 0 0 0.999048"
                  type="mesh"
                  mesh="leg_l_r"
                  rgba="0.8 0.8 0.8 1"
                  contype="0" conaffinity="0"/>

            <!-- Example right foot geom or site (rename if needed) -->
            <geom name = "right_foot" pos="-0.15 0.02 0" type="sphere" size="0.02" contype="1" conaffinity="1"/>
            <site name="right_foot" pos="-0.15 0.02 0" size="0.01"/>


          </body>
        </body>
      </body>
    </body>
  </worldbody>

  <!-- Sensors -->
  <sensor>
    <!-- Existing sensors from your original file -->
    <framepos   name="torso_position"   objtype="xbody"  objname="base_link"/>
    <subtreelinvel name="torso_subtreelinvel" body="base_link"/>
    <framezaxis name="torso_zaxis"      objtype="xbody"  objname="base_link"/>

    <!-- IMU-type sensors referencing imu_torso (Go1 style) -->
    <gyro           site="imu_torso" name="gyro_imu_torso"/>
    <velocimeter    site="imu_torso" name="local_linvel_imu_torso"/>
    <accelerometer  site="imu_torso" name="accelerometer_imu_torso"/>
    <framepos       objtype="site"   objname="imu_torso" name="position_imu_torso"/>
    <framezaxis     objtype="site"   objname="imu_torso" name="upvector_imu_torso"/>
    <framexaxis     objtype="site"   objname="imu_torso" name="forwardvector_imu_torso"/>
    <framelinvel    objtype="site"   objname="imu_torso" name="global_linvel_imu_torso"/>
    <frameangvel    objtype="site"   objname="imu_torso" name="global_angvel_imu_torso"/>
    <framequat      objtype="site"   objname="imu_torso" name="orientation_imu_torso"/>

    <!-- Foot sensors: measure each foot’s velocity in global coords, plus position relative to IMU -->
    <framelinvel objtype="site" objname="left_foot"  name="left_foot_global_linvel"/>
    <framelinvel objtype="site" objname="right_foot" name="right_foot_global_linvel"/>

    <!-- Positions of the feet in the local IMU frame (optional) -->
    <framepos objtype="site" objname="left_foot"  name="left_foot_pos_in_imu"
              reftype="site" refname="imu_torso"/>
    <framepos objtype="site" objname="right_foot" name="right_foot_pos_in_imu"
              reftype="site" refname="imu_torso"/>
  </sensor>

  <!-- Actuators -->
  <actuator>
    <motor name="J_HIP_L"  joint="J_HIP_L"  gear="1"/>
    <motor name="J_HIP_R"  joint="J_HIP_R"  gear="1"/>
    <motor name="J_AB_L"   joint="J_AB_L"   gear="1"/>
    <motor name="J_AB_R"   joint="J_AB_R"   gear="1"/>
    <motor name="J_KNEE_L" joint="J_KNEE_L" gear="1"/>
    <motor name="J_KNEE_R" joint="J_KNEE_R" gear="1"/>
  </actuator>
</mujoco>
